<?xml version="1.0" ?>
<!-- =================================================================================== -->
<!-- |    This document was autogenerated by xacro from robucar.urdf.xacro             | -->
<!-- |    EDITING THIS FILE BY HAND IS NOT RECOMMENDED                                 | -->
<!-- =================================================================================== -->
<robot name="Robucar" xmlns:controller="http://playerstage.sourceforge.net/gazebo/xmlschema/#controller" xmlns:xacro="http://playerstage.sourceforge.net/gazebo/xmlschema/#interface">
  <!-- Robot part macros are included here. -->
  <!-- Parameters -->
  <!-- Robot parts -->
  <link name="base_link">
    <inertial>
      <mass value="250.0"/>
      <inertia ixx="20.83" ixy="10.0" ixz="10.0" iyy="83.33" iyz="10.0" izz="83.33"/>
    </inertial>
    <visual>
      <geometry>
        <box size="2.9 1.1 0.93"/>
      </geometry>
      <material name="blue">
        <color rgba="0 0 .8 1"/>
      </material>
      <origin rpy="0 0 0" xyz="0 0 0"/>
    </visual>
    <collision>
      <origin xyz="0 0 0"/>
      <geometry>
        <box size="2.9 1.1 0.93"/>
      </geometry>
      <origin rpy="0 0 0" xyz="0 0 0"/>
    </collision>
  </link>
  <gazebo reference="base_link">
    <material>Gazebo/Blue</material>
    <turnGravityOff>false</turnGravityOff>
  </gazebo>
  <link name="front_axle">
    <inertial>
      <mass value="1.0"/>
      <inertia ixx="1.0" ixy="0.0" ixz="0.0" iyy="1.0" iyz="0.0" izz="1.0"/>
    </inertial>
    <visual>
      <geometry>
        <cylinder length="1.2" radius="0.02"/>
      </geometry>
      <origin rpy="1.57075 0 0" xyz="0 0 0"/>
      <material name="black">
        <color rgba="0.1 0 0 1"/>
      </material>
    </visual>
    <collision>
      <geometry>
        <cylinder length="1.2" radius="0.02"/>
      </geometry>
      <origin rpy="1.57075 0 0" xyz="0 0 0"/>
    </collision>
  </link>
  <gazebo reference="front_axle">
    <material>Gazebo/Black</material>
    <turnGravityOff>false</turnGravityOff>
  </gazebo>
  <joint name="base_to_front_axle" type="fixed">
    <parent link="base_link"/>
    <child link="front_axle"/>
    <origin xyz="0.6 0 -.3"/>
  </joint>
  <link name="front_left_bearing">
    <inertial>
      <mass value="0.1"/>
      <inertia ixx="1.0" ixy="0.0" ixz="0.0" iyy="1.0" iyz="0.0" izz="1.0"/>
    </inertial>
    <visual>
      <geometry>
        <cylinder length=".02" radius="0.02"/>
      </geometry>
      <origin rpy="1.57075 0 0" xyz="0 0 0"/>
      <material name="yellow">
        <color rgba="0.8 .8 0 1"/>
      </material>
    </visual>
    <collision>
      <geometry>
        <cylinder length=".02" radius="0.02"/>
      </geometry>
      <origin rpy="1.57075 0 0" xyz="0 0 0"/>
    </collision>
  </link>
  <gazebo reference="front_left_bearing">
    <material>Gazebo/Yellow</material>
    <turnGravityOff>false</turnGravityOff>
  </gazebo>
  <joint name="front_axle_to_front_left_bearing" type="revolute">
    <axis xyz="0 0 1"/>
    <parent link="front_axle"/>
    <child link="front_left_bearing"/>
    <origin xyz="0 0.6 0"/>
    <limit effort="1000" lower="-0.2" upper="0.2" velocity="1000"/>
  </joint>
  <link name="front_left_wheel">
    <inertial>
      <mass value="6.0"/>
      <inertia ixx="1.0" ixy="0.0" ixz="0.0" iyy="1.0" iyz="0.0" izz="1.0"/>
    </inertial>
    <visual>
      <geometry>
        <cylinder length=".05" radius="0.3"/>
      </geometry>
      <origin rpy="1.57075 0 0" xyz="0 0 0"/>
      <material name="green">
        <color rgba="0 .8 0 1"/>
      </material>
    </visual>
    <collision>
      <geometry>
        <cylinder length=".05" radius="0.3"/>
      </geometry>
      <origin rpy="1.57075 0 0" xyz="0 0 0"/>
    </collision>
  </link>
  <gazebo reference="front_left_wheel">
    <material>Gazebo/Green</material>
    <turnGravityOff>false</turnGravityOff>
  </gazebo>
  <joint name="front_left_bearing_to_front_left_wheel" type="continuous">
    <axis xyz="0 1 0"/>
    <parent link="front_left_bearing"/>
    <child link="front_left_wheel"/>
    <origin xyz="0 0.02 0"/>
  </joint>
  <link name="front_right_bearing">
    <inertial>
      <mass value="0.1"/>
      <inertia ixx="1.0" ixy="0.0" ixz="0.0" iyy="1.0" iyz="0.0" izz="1.0"/>
    </inertial>
    <visual>
      <geometry>
        <cylinder length=".02" radius="0.02"/>
      </geometry>
      <origin rpy="1.57075 0 0" xyz="0 0 0"/>
      <material name="yellow">
        <color rgba="0.8 .8 0 1"/>
      </material>
    </visual>
    <collision>
      <geometry>
        <cylinder length=".02" radius="0.02"/>
      </geometry>
      <origin rpy="1.57075 0 0" xyz="0 0 0"/>
    </collision>
  </link>
  <gazebo reference="front_right_bearing">
    <material>Gazebo/Yellow</material>
    <turnGravityOff>false</turnGravityOff>
  </gazebo>
  <joint name="front_axle_to_front_right_bearing" type="revolute">
    <axis xyz="0 0 1"/>
    <parent link="front_axle"/>
    <child link="front_right_bearing"/>
    <origin xyz="0 -0.6 0"/>
    <limit effort="1000" lower="-0.2" upper="0.2" velocity="1000"/>
  </joint>
  <link name="front_right_wheel">
    <inertial>
      <mass value="6.0"/>
      <inertia ixx="1.0" ixy="0.0" ixz="0.0" iyy="1.0" iyz="0.0" izz="1.0"/>
    </inertial>
    <visual>
      <geometry>
        <cylinder length=".05" radius="0.3"/>
      </geometry>
      <origin rpy="1.57075 0 0" xyz="0 0 0"/>
      <material name="green">
        <color rgba="0 .8 0 1"/>
      </material>
    </visual>
    <collision>
      <geometry>
        <cylinder length=".05" radius="0.3"/>
      </geometry>
      <origin rpy="1.57075 0 0" xyz="0 0 0"/>
    </collision>
  </link>
  <gazebo reference="front_right_wheel">
    <material>Gazebo/Green</material>
    <turnGravityOff>false</turnGravityOff>
  </gazebo>
  <joint name="front_right_bearing_to_front_right_wheel" type="continuous">
    <axis xyz="0 1 0"/>
    <parent link="front_right_bearing"/>
    <child link="front_right_wheel"/>
    <origin xyz="0 -0.02 0"/>
  </joint>
  <link name="back_axle">
    <inertial>
      <mass value="1.0"/>
      <inertia ixx="1.0" ixy="0.0" ixz="0.0" iyy="1.0" iyz="0.0" izz="1.0"/>
    </inertial>
    <visual>
      <geometry>
        <cylinder length="1.2" radius="0.02"/>
      </geometry>
      <origin rpy="1.57075 0 0" xyz="0 0 0"/>
      <material name="black">
        <color rgba="0.1 0 0 1"/>
      </material>
    </visual>
    <collision>
      <geometry>
        <cylinder length="1.2" radius="0.02"/>
      </geometry>
      <origin rpy="1.57075 0 0" xyz="0 0 0"/>
    </collision>
  </link>
  <gazebo reference="back_axle">
    <material>Gazebo/Black</material>
    <turnGravityOff>false</turnGravityOff>
  </gazebo>
  <joint name="base_to_back_axle" type="fixed">
    <parent link="base_link"/>
    <child link="back_axle"/>
    <origin xyz="-0.6 0 -.3"/>
  </joint>
  <link name="back_left_bearing">
    <inertial>
      <mass value="0.1"/>
      <inertia ixx="1.0" ixy="0.0" ixz="0.0" iyy="1.0" iyz="0.0" izz="1.0"/>
    </inertial>
    <visual>
      <geometry>
        <cylinder length=".02" radius="0.02"/>
      </geometry>
      <origin rpy="1.57075 0 0" xyz="0 0 0"/>
      <material name="yellow">
        <color rgba="0.8 .8 0 1"/>
      </material>
    </visual>
    <collision>
      <geometry>
        <cylinder length=".02" radius="0.02"/>
      </geometry>
      <origin rpy="1.57075 0 0" xyz="0 0 0"/>
    </collision>
  </link>
  <gazebo reference="back_left_bearing">
    <material>Gazebo/Yellow</material>
    <turnGravityOff>false</turnGravityOff>
  </gazebo>
  <joint name="back_axle_to_back_left_bearing" type="revolute">
    <axis xyz="0 0 1"/>
    <parent link="back_axle"/>
    <child link="back_left_bearing"/>
    <origin xyz="0 0.6 0"/>
    <limit effort="1000" lower="-0.2" upper="0.2" velocity="1000"/>
  </joint>
  <link name="back_left_wheel">
    <inertial>
      <mass value="6.0"/>
      <inertia ixx="1.0" ixy="0.0" ixz="0.0" iyy="1.0" iyz="0.0" izz="1.0"/>
    </inertial>
    <visual>
      <geometry>
        <cylinder length=".05" radius="0.3"/>
      </geometry>
      <origin rpy="1.57075 0 0" xyz="0 0 0"/>
      <material name="green">
        <color rgba="0 .8 0 1"/>
      </material>
    </visual>
    <collision>
      <geometry>
        <cylinder length=".05" radius="0.3"/>
      </geometry>
      <origin rpy="1.57075 0 0" xyz="0 0 0"/>
    </collision>
  </link>
  <gazebo reference="back_left_wheel">
    <material>Gazebo/Green</material>
    <turnGravityOff>false</turnGravityOff>
  </gazebo>
  <joint name="back_left_bearing_to_back_left_wheel" type="continuous">
    <axis xyz="0 1 0"/>
    <parent link="back_left_bearing"/>
    <child link="back_left_wheel"/>
    <origin xyz="0 0.02 0"/>
  </joint>
  <link name="back_right_bearing">
    <inertial>
      <mass value="0.1"/>
      <inertia ixx="1.0" ixy="0.0" ixz="0.0" iyy="1.0" iyz="0.0" izz="1.0"/>
    </inertial>
    <visual>
      <geometry>
        <cylinder length=".02" radius="0.02"/>
      </geometry>
      <origin rpy="1.57075 0 0" xyz="0 0 0"/>
      <material name="yellow">
        <color rgba="0.8 .8 0 1"/>
      </material>
    </visual>
    <collision>
      <geometry>
        <cylinder length=".02" radius="0.02"/>
      </geometry>
      <origin rpy="1.57075 0 0" xyz="0 0 0"/>
    </collision>
  </link>
  <gazebo reference="back_right_bearing">
    <material>Gazebo/Yellow</material>
    <turnGravityOff>false</turnGravityOff>
  </gazebo>
  <joint name="back_axle_to_back_right_bearing" type="revolute">
    <axis xyz="0 0 1"/>
    <parent link="back_axle"/>
    <child link="back_right_bearing"/>
    <origin xyz="0 -0.6 0"/>
    <limit effort="1000" lower="-0.2" upper="0.2" velocity="1000"/>
  </joint>
  <link name="back_right_wheel">
    <inertial>
      <mass value="6.0"/>
      <inertia ixx="1.0" ixy="0.0" ixz="0.0" iyy="1.0" iyz="0.0" izz="1.0"/>
    </inertial>
    <visual>
      <geometry>
        <cylinder length=".05" radius="0.3"/>
      </geometry>
      <origin rpy="1.57075 0 0" xyz="0 0 0"/>
      <material name="green">
        <color rgba="0 .8 0 1"/>
      </material>
    </visual>
    <collision>
      <geometry>
        <cylinder length=".05" radius="0.3"/>
      </geometry>
      <origin rpy="1.57075 0 0" xyz="0 0 0"/>
    </collision>
  </link>
  <gazebo reference="back_right_wheel">
    <material>Gazebo/Green</material>
    <turnGravityOff>false</turnGravityOff>
  </gazebo>
  <joint name="back_right_bearing_to_back_right_wheel" type="continuous">
    <axis xyz="0 1 0"/>
    <parent link="back_right_bearing"/>
    <child link="back_right_wheel"/>
    <origin xyz="0 -0.02 0"/>
  </joint>
  <link name="head">
    <inertial>
      <mass value="0.1"/>
      <inertia ixx="1.0" ixy="0.0" ixz="0.0" iyy="1.0" iyz="0.0" izz="1.0"/>
    </inertial>
    <visual>
      <geometry>
        <box size="0.2 0.2 0.2"/>
      </geometry>
      <origin rpy="0 0 0" xyz="0 0 0"/>
      <material name="red">
        <color rgba="0.8 0 0 1"/>
      </material>
    </visual>
    <collision>
      <geometry>
        <box size="0.2 0.2 0.2"/>
      </geometry>
      <origin rpy="0 0 0" xyz="0 0 0"/>
    </collision>
  </link>
  <gazebo reference="head">
    <material>Gazebo/Red</material>
    <turnGravityOff>true</turnGravityOff>
  </gazebo>
  <joint name="base_to_head" type="fixed">
    <parent link="base_link"/>
    <child link="head"/>
    <origin xyz="1.45 0 0"/>
  </joint>
  <!--gazebo>
    <controller:robucar_plugin name="robucar_plugin_controller" plugin="librobucar_plugin.so">

      <alwaysOn>true</alwaysOn>
      <update>100</update>
      <updateRate>100.0</updateRate>

      <frontAxleName>base_to_front_axle</frontAxleName>
      <frontLeftBearingName>front_axle_to_front_left_bearing</frontLeftBearingName>
      <frontLeftWheelName>front_left_bearing_to_front_left_wheel</frontLeftWheelName>
      <frontRightBearingName>front_axle_to_front_right_bearing</frontRightBearingName>
      <frontRightWheelName>front_right_bearing_to_front_right_wheel</frontRightWheelName>
      <backAxleName>base_to_back_axle</backAxleName>
      <backLeftBearingName>back_axle_to_back_left_bearing</backLeftBearingName>
      <backLeftWheelName>back_left_bearing_to_back_left_wheel</backLeftWheelName>
      <backRightBearingName>back_axle_to_back_right_bearing</backRightBearingName>
      <backRightWheelName>back_right_bearing_to_back_right_wheel</backRightWheelName>

      <wheelRadius>${wheel_radius}</wheelRadius>
      <axleLength>${axle_length}</axleLength>
      <axleSeparation>${axle_separation}</axleSeparation>

      <robotNamespace>/robucar</robotNamespace>
      <topicName>cmd_vel</topicName>

    </controller:robucar_plugin>
  </gazebo-->
</robot>

